<?xml version="1.0" encoding="utf-8"?>
<!-- =================================================================================== -->
<!-- |    This document was autogenerated by xacro from /root/catkin_ws/src/ridgeback_manipulation/ridgeback_franka_description/urdf/ridgeback_dual_fr3_description.urdf.xacro | -->
<!-- |    EDITING THIS FILE BY HAND IS NOT RECOMMENDED                                 | -->
<!-- =================================================================================== -->
<robot name="ridgeback">
  <material name="dark_grey">
    <color rgba="0.2 0.2 0.2 1.0"/>
  </material>
  <material name="light_grey">
    <color rgba="0.4 0.4 0.4 1.0"/>
  </material>
  <material name="red">
    <color rgba="0.8 0.0 0.0 1.0"/>
  </material>
  <material name="white">
    <color rgba="0.9 0.9 0.9 1.0"/>
  </material>
  <material name="yellow">
    <color rgba="0.8 0.8 0.0 1.0"/>
  </material>
  <material name="black">
    <color rgba="0.15 0.15 0.15 1.0"/>
  </material>
  <link name="front_rocker_link">
    <visual>
      <origin rpy="1.57079632679 0 1.57079632679" xyz="0 0 0"/>
      <geometry>
        <mesh filename="ridgeback_meshes/rocker.stl"/>
      </geometry>
      <material name="black"/>
    </visual>
    <inertial>
      <origin rpy="1.57079632679 0 1.57079632679" xyz="0 0 0"/>
      <mass value="10.267"/>
      <inertia ixx="0.0288" ixy="2.20484e-6" ixz="-1.3145e-5" iyy="0.4324" iyz="1.8944e-3" izz="0.4130"/>
    </inertial>
  </link>
  <joint name="front_rocker" type="revolute">
    <parent link="axle_link"/>
    <child link="front_rocker_link"/>
    <origin rpy="0 0 0" xyz="0.319 0 0"/>
    <axis xyz="1 0 0"/>
    <limit effort="0" lower="-0.08726" upper="0.08726" velocity="0"/>
  </joint>
  <link name="front_left_wheel_link">
    <visual>
      <origin rpy="1.57079632679 0 0" xyz="0 0 0"/>
      <geometry>
        <mesh filename="ridgeback_meshes/wheel.stl"/>
      </geometry>
      <material name="black"/>
    </visual>
    <collision>
      <origin rpy="1.57079632679 0 0" xyz="0 0 0"/>
      <geometry>
        <cylinder length="0.079" radius="0.0759"/>
      </geometry>
    </collision>
    <inertial>
      <origin rpy="0 0 0" xyz="0 0 0"/>
      <mass value="2.3"/>
      <inertia ixx="3.3212e-3" ixy="0" ixz="0" iyy="6.6424e-3" iyz="0" izz="3.3212e-3"/>
    </inertial>
  </link>
  <joint name="front_left_wheel" type="continuous">
    <parent link="front_rocker_link"/>
    <child link="front_left_wheel_link"/>
    <origin rpy="0 0 0" xyz="0 0.2755 0"/>
    <axis xyz="0 1 0"/>
  </joint>
  <transmission name="front_wheel_trans">
    <type>transmission_interface/SimpleTransmission</type>
    <joint name="front_left_wheel">
      <hardwareInterface>hardware_interface/VelocityJointInterface</hardwareInterface>
    </joint>
    <actuator name="front_left_actuator">
      <mechanicalReduction>1</mechanicalReduction>
    </actuator>
  </transmission>
  <link name="front_right_wheel_link">
    <visual>
      <origin rpy="1.57079632679 0 0" xyz="0 0 0"/>
      <geometry>
        <mesh filename="ridgeback_meshes/wheel.stl"/>
      </geometry>
      <material name="black"/>
    </visual>
    <collision>
      <origin rpy="1.57079632679 0 0" xyz="0 0 0"/>
      <geometry>
        <cylinder length="0.079" radius="0.0759"/>
      </geometry>
    </collision>
    <inertial>
      <origin rpy="0 0 0" xyz="0 0 0"/>
      <mass value="2.3"/>
      <inertia ixx="3.3212e-3" ixy="0" ixz="0" iyy="6.6424e-3" iyz="0" izz="3.3212e-3"/>
    </inertial>
  </link>
  <joint name="front_right_wheel" type="continuous">
    <parent link="front_rocker_link"/>
    <child link="front_right_wheel_link"/>
    <origin rpy="0 0 0" xyz="0 -0.2755 0"/>
    <axis xyz="0 1 0"/>
  </joint>
  <transmission name="front_wheel_trans">
    <type>transmission_interface/SimpleTransmission</type>
    <joint name="front_right_wheel">
      <hardwareInterface>hardware_interface/VelocityJointInterface</hardwareInterface>
    </joint>
    <actuator name="front_right_actuator">
      <mechanicalReduction>1</mechanicalReduction>
    </actuator>
  </transmission>
  <link name="rear_rocker_link">
    <visual>
      <origin rpy="1.57079632679 0 1.57079632679" xyz="0 0 0"/>
      <geometry>
        <mesh filename="ridgeback_meshes/rocker.stl"/>
      </geometry>
      <material name="black"/>
    </visual>
    <inertial>
      <origin rpy="1.57079632679 0 1.57079632679" xyz="0 0 0"/>
      <mass value="10.267"/>
      <inertia ixx="0.0288" ixy="2.20484e-6" ixz="-1.3145e-5" iyy="0.4324" iyz="1.8944e-3" izz="0.4130"/>
    </inertial>
  </link>
  <joint name="rear_rocker" type="fixed">
    <parent link="axle_link"/>
    <child link="rear_rocker_link"/>
    <origin rpy="0 0 0" xyz="-0.319 0 0"/>
    <axis xyz="1 0 0"/>
    <limit effort="0" velocity="0"/>
  </joint>
  <link name="rear_left_wheel_link">
    <visual>
      <origin rpy="1.57079632679 0 0" xyz="0 0 0"/>
      <geometry>
        <mesh filename="ridgeback_meshes/wheel.stl"/>
      </geometry>
      <material name="black"/>
    </visual>
    <collision>
      <origin rpy="1.57079632679 0 0" xyz="0 0 0"/>
      <geometry>
        <cylinder length="0.079" radius="0.0759"/>
      </geometry>
    </collision>
    <inertial>
      <origin rpy="0 0 0" xyz="0 0 0"/>
      <mass value="2.3"/>
      <inertia ixx="3.3212e-3" ixy="0" ixz="0" iyy="6.6424e-3" iyz="0" izz="3.3212e-3"/>
    </inertial>
  </link>
  <joint name="rear_left_wheel" type="continuous">
    <parent link="rear_rocker_link"/>
    <child link="rear_left_wheel_link"/>
    <origin rpy="0 0 0" xyz="0 0.2755 0"/>
    <axis xyz="0 1 0"/>
  </joint>
  <transmission name="rear_wheel_trans">
    <type>transmission_interface/SimpleTransmission</type>
    <joint name="rear_left_wheel">
      <hardwareInterface>hardware_interface/VelocityJointInterface</hardwareInterface>
    </joint>
    <actuator name="rear_left_actuator">
      <mechanicalReduction>1</mechanicalReduction>
    </actuator>
  </transmission>
  <link name="rear_right_wheel_link">
    <visual>
      <origin rpy="1.57079632679 0 0" xyz="0 0 0"/>
      <geometry>
        <mesh filename="ridgeback_meshes/wheel.stl"/>
      </geometry>
      <material name="black"/>
    </visual>
    <collision>
      <origin rpy="1.57079632679 0 0" xyz="0 0 0"/>
      <geometry>
        <cylinder length="0.079" radius="0.0759"/>
      </geometry>
    </collision>
    <inertial>
      <origin rpy="0 0 0" xyz="0 0 0"/>
      <mass value="2.3"/>
      <inertia ixx="3.3212e-3" ixy="0" ixz="0" iyy="6.6424e-3" iyz="0" izz="3.3212e-3"/>
    </inertial>
  </link>
  <joint name="rear_right_wheel" type="continuous">
    <parent link="rear_rocker_link"/>
    <child link="rear_right_wheel_link"/>
    <origin rpy="0 0 0" xyz="0 -0.2755 0"/>
    <axis xyz="0 1 0"/>
  </joint>
  <transmission name="rear_wheel_trans">
    <type>transmission_interface/SimpleTransmission</type>
    <joint name="rear_right_wheel">
      <hardwareInterface>hardware_interface/VelocityJointInterface</hardwareInterface>
    </joint>
    <actuator name="rear_right_actuator">
      <mechanicalReduction>1</mechanicalReduction>
    </actuator>
  </transmission>
  <link name="base_link"/>
  <joint name="base_link_joint" type="fixed">
    <origin rpy="0 0 0" xyz="0 0 0"/>
    <parent link="base_link"/>
    <child link="chassis_link"/>
  </joint>
  <link name="chassis_link">
    <visual>
      <origin rpy="0 0 0" xyz="0 0 0"/>
      <geometry>
        <mesh filename="ridgeback_meshes/body.stl"/>
      </geometry>
      <material name="black"/>
    </visual>
    <collision>
      <origin xyz="0 0 0"/>
      <geometry>
        <mesh filename="ridgeback_meshes/body-collision.stl"/>
      </geometry>
    </collision>
    <inertial>
      <origin rpy="1.57079632679 0 1.57079632679" xyz="0.012 0.002 0.067"/>
      <mass value="165.304"/>
      <inertia ixx="4.4744" ixy="0.03098" ixz="0.003647" iyy="7.1624" iyz="0.1228" izz="4.6155"/>
    </inertial>
  </link>
  <link name="riser_link">
    <visual>
      <origin rpy="0 0 0.785398163397" xyz="0 0 0.0275"/>
      <geometry>
        <box size="0.493 0.493 0.055"/>
      </geometry>
      <material name="light_grey"/>
    </visual>
    <collision>
      <origin rpy="0 0 0.785398163397" xyz="0 0 0.0275"/>
      <geometry>
        <box size="0.493 0.493 0.055"/>
      </geometry>
    </collision>
  </link>
  <joint name="riser_link_joint" type="fixed">
    <origin rpy="0 0 0" xyz="0 0 0.22"/>
    <parent link="chassis_link"/>
    <child link="riser_link"/>
  </joint>
  <joint name="right_side_cover_link_joint" type="fixed">
    <origin rpy="0 0 0" xyz="0 0 0"/>
    <parent link="chassis_link"/>
    <child link="right_side_cover_link"/>
  </joint>
  <joint name="left_side_cover_link_joint" type="fixed">
    <origin rpy="0 0 0" xyz="0 0 0"/>
    <parent link="chassis_link"/>
    <child link="left_side_cover_link"/>
  </joint>
  <link name="left_side_cover_link">
    <visual>
      <origin rpy="0 0 3.14159265359" xyz="0 0 0"/>
      <geometry>
        <mesh filename="ridgeback_meshes/side-cover.stl"/>
      </geometry>
      <material name="yellow"/>
    </visual>
  </link>
  <link name="right_side_cover_link">
    <visual>
      <origin rpy="0 0 0" xyz="0 0 0"/>
      <geometry>
        <mesh filename="ridgeback_meshes/side-cover.stl"/>
      </geometry>
      <material name="yellow"/>
    </visual>
  </link>
  <joint name="front_cover_link_joint" type="fixed">
    <origin rpy="0 0 0" xyz="0 0 0"/>
    <parent link="chassis_link"/>
    <child link="front_cover_link"/>
  </joint>
  <link name="front_cover_link">
    <visual>
      <origin rpy="0 0 0" xyz="0 0 0"/>
      <geometry>
        <mesh filename="ridgeback_meshes/end-cover.stl"/>
      </geometry>
      <material name="black"/>
    </visual>
  </link>
  <joint name="rear_cover_link_joint" type="fixed">
    <origin rpy="0 0 0" xyz="0 0 0"/>
    <parent link="chassis_link"/>
    <child link="rear_cover_link"/>
  </joint>
  <link name="rear_cover_link">
    <visual>
      <origin rpy="0 0 3.14159265359" xyz="0 0 0"/>
      <geometry>
        <mesh filename="ridgeback_meshes/end-cover.stl"/>
      </geometry>
      <material name="black"/>
    </visual>
  </link>
  <joint name="front_lights_link_joint" type="fixed">
    <origin rpy="0 0 0" xyz="0 0 0"/>
    <parent link="chassis_link"/>
    <child link="front_lights_link"/>
  </joint>
  <joint name="rear_lights_link_joint" type="fixed">
    <origin rpy="0 0 0" xyz="0 0 0"/>
    <parent link="chassis_link"/>
    <child link="rear_lights_link"/>
  </joint>
  <link name="front_lights_link">
    <visual>
      <origin rpy="0 0 0" xyz="0 0 0"/>
      <geometry>
        <mesh filename="ridgeback_meshes/lights.stl"/>
      </geometry>
      <material name="white"/>
    </visual>
  </link>
  <link name="rear_lights_link">
    <visual>
      <origin rpy="0 0 3.14159265359" xyz="0 0 0"/>
      <geometry>
        <mesh filename="ridgeback_meshes/lights.stl"/>
      </geometry>
      <material name="black"/>
    </visual>
  </link>
  <joint name="top_link_joint" type="fixed">
    <origin rpy="0 0 0" xyz="0 0 -0.22"/>
    <parent link="riser_link"/>
    <child link="top_link"/>
  </joint>
  <link name="top_link">
    <visual>
      <origin rpy="0 0 0" xyz="0 0 0"/>
      <geometry>
        <mesh filename="ridgeback_meshes/top.stl"/>
      </geometry>
      <material name="black"/>
    </visual>
    <collision>
      <origin rpy="0 0 0" xyz="0 0 0"/>
      <geometry>
        <mesh filename="ridgeback_meshes/top.stl"/>
      </geometry>
    </collision>
  </link>
  <joint name="axle_joint" type="fixed">
    <origin rpy="0 0 0" xyz="0 0 0.05"/>
    <parent link="chassis_link"/>
    <child link="axle_link"/>
  </joint>
  <link name="axle_link">
    <visual>
      <origin rpy="0 1.57079632679 0" xyz="0 0 0"/>
      <geometry>
        <mesh filename="ridgeback_meshes/axle.stl"/>
      </geometry>
      <material name="black"/>
    </visual>
  </link>
  <link name="imu_link">
    <inertial>
      <mass value="0.001"/>
      <origin rpy="0 0 0" xyz="0 0 0"/>
      <inertia ixx="1e-09" ixy="0.0" ixz="0.0" iyy="1e-09" iyz="0.0" izz="1e-09"/>
    </inertial>
  </link>
  <joint name="imu_joint" type="fixed">
    <parent link="chassis_link"/>
    <child link="imu_link"/>
    <origin rpy="0 0 0" xyz="0.2085 -0.2902 0.1681"/>
  </joint>
  <link name="mid_mount"/>
  <joint name="mid_mount_joint" type="fixed">
    <parent link="riser_link"/>
    <child link="mid_mount"/>
    <origin rpy="0 0 0" xyz="0 0 0.06"/>
  </joint>
  <link name="left_fr3_root"/>
  <joint name="left_fr3_mount_joint" type="fixed">
    <parent link="mid_mount"/>
    <child link="left_fr3_root"/>
    <origin rpy="0 0 0" xyz="0.21 0.20 0.0"/>
  </joint>
  <!-- RIGHT ARM -->
  <link name="right_fr3_root"/>
  <joint name="right_fr3_mount_joint" type="fixed">
    <parent link="mid_mount"/>
    <child link="right_fr3_root"/>
    <origin rpy="0 0 0" xyz="0.21 -0.20 0.0"/>
  </joint>


  <!-- LEFT ARM BODY -->
<!-- safety_distance: Minimum safety distance in [m] by which the collision volumes are expanded and which is enforced during robot motions -->
  <!-- robot_type: Namespace of the robot arm. Serves to differentiate between arms in case of multiple instances. -->
  <!-- joint_limits: description of the joint limits that comes from a YAML file. Example definition: ${xacro.load_yaml('$(find franka_description)/robots/fr3/joint_limits.yaml')} -->
  <!-- kinematics: description of the kinematics that comes from a YAML file. Example definition: ${xacro.load_yaml('$(find franka_description)/robots/fr3/kinematics.yaml')} -->
  <!-- inertials: description of the inertials that comes from a YAML file. Example definition: ${xacro.load_yaml('$(find franka_description)/robots/fr3/inertials.yaml')} -->
  <!-- dynamics: description of the dynamics that comes from a YAML file. Example definition: ${xacro.load_yaml('$(find franka_description)/robots/fr3/dynamics.yaml')} -->
  <joint name="left_fr3_base_joint" type="fixed">
    <parent link="left_fr3_root"/>
    <child link="left_fr3_link0"/>
    <origin rpy="0 0 0" xyz="0 0 0"/>
  </joint>
  <!-- sub-link defining detailed meshes for collision with environment -->
  <link name="left_fr3_link0">
    <visual name="left_fr3_link0_visual">
      <geometry>
        <mesh filename="fr3_meshes/visual/link0.dae"/>
      </geometry>
    </visual>
    <collision name="left_fr3_link0_collision">
      <geometry>
        <mesh filename="fr3_meshes/collision/link0.stl"/>
      </geometry>
    </collision>
    <inertial>
      <origin rpy="0 0 0" xyz="-0.0172 0.0004 0.0745"/>
      <mass value="2.3966"/>
      <inertia ixx="0.009" ixy="0.0" ixz="0.002" iyy="0.0115" iyz="0.0" izz="0.0085"/>
    </inertial>
  </link>
  <link name="left_fr3_link0_accelerometer_top">
      </link>
  <joint name="left_fr3_link0_accelerometer_top_joint" type="fixed">
    <origin rpy="3.1416 0.0 0.0" xyz="-0.017402 -0.007872 0.04715"/>
    <parent link="left_fr3_link0"/>
    <child link="left_fr3_link0_accelerometer_top"/>
  </joint>
  <link name="left_fr3_link0_accelerometer_bottom">
      </link>
  <joint name="left_fr3_link0_accelerometer_bottom_joint" type="fixed">
    <origin rpy="0.0 0.0 -1.5708" xyz="-0.019739 0.0015506 0.05075"/>
    <parent link="left_fr3_link0"/>
    <child link="left_fr3_link0_accelerometer_bottom"/>
  </joint>
  <!-- sub-link defining detailed meshes for collision with environment -->
  <link name="left_fr3_link1">
    <visual name="left_fr3_link1_visual">
      <geometry>
        <mesh filename="fr3_meshes/visual/link1.dae"/>
      </geometry>
    </visual>
    <collision name="left_fr3_link1_collision">
      <geometry>
        <mesh filename="fr3_meshes/collision/link1.stl"/>
      </geometry>
    </collision>
    <inertial>
      <origin rpy="0 0 0" xyz="0.0000004128 -0.0181251324 -0.0386035970"/>
      <mass value="2.9274653454"/>
      <inertia ixx="0.0239273164851" ixy="1.33179034557e-05" ixz="-0.000114047749186" iyy="0.0224821613276" iyz="-0.00199503206282" izz="0.00635009825853"/>
    </inertial>
  </link>
  <link name="left_fr3_link1_accelerometer_top">
      </link>
  <joint name="left_fr3_link1_accelerometer_top_joint" type="fixed">
    <origin rpy="-1.5708 0.0 3.1416" xyz="0.017402 -0.093352 -0.00787"/>
    <parent link="left_fr3_link1"/>
    <child link="left_fr3_link1_accelerometer_top"/>
  </joint>
  <link name="left_fr3_link1_accelerometer_bottom">
      </link>
  <joint name="left_fr3_link1_accelerometer_bottom_joint" type="fixed">
    <origin rpy="-1.5708 1.5708 0.0" xyz="0.01974 -0.08975 0.00155"/>
    <parent link="left_fr3_link1"/>
    <child link="left_fr3_link1_accelerometer_bottom"/>
  </joint>
  <joint name="left_fr3_joint1" type="revolute">
    <origin rpy="0 0 0" xyz="0 0 0.333"/>
    <parent link="left_fr3_link0"/>
    <child link="left_fr3_link1"/>
    <axis xyz="0 0 1"/>
    <limit effort="87.0" lower="-2.9007" upper="2.9007" velocity="2.62"/>
    <safety_controller k_position="100.0" k_velocity="40.0" soft_lower_limit="-2.9007" soft_upper_limit="2.9007"/>
    <position_based_velocity_limits deceleration_limit="6.0" velocity_offset="0.652"/>
    <dynamics D="1" K="7000" damping="0.003" friction="0.2" gear_ratio="120.0" motor_inertia="4.206399e-05" mu_coulomb="0" mu_viscous="16"/>
  </joint>
  <!-- sub-link defining detailed meshes for collision with environment -->
  <link name="left_fr3_link2">
    <visual name="left_fr3_link2_visual">
      <geometry>
        <mesh filename="fr3_meshes/visual/link2.dae"/>
      </geometry>
    </visual>
    <collision name="left_fr3_link2_collision">
      <geometry>
        <mesh filename="fr3_meshes/collision/link2.stl"/>
      </geometry>
    </collision>
    <inertial>
      <origin rpy="0 0 0" xyz="0.0031828864 -0.0743221644 0.0088146084"/>
      <mass value="2.9355370338"/>
      <inertia ixx="0.0419389462576" ixy="0.000202573315211" ixz="0.00407778422718" iyy="0.0251451488501" iyz="-0.00422521580066" izz="0.0617021447289"/>
    </inertial>
  </link>
  <link name="left_fr3_link2_accelerometer_top">
      </link>
  <joint name="left_fr3_link2_accelerometer_top_joint" type="fixed">
    <origin rpy="1.5708 0.0 3.1416" xyz="0.017403 -0.11715 0.00787"/>
    <parent link="left_fr3_link2"/>
    <child link="left_fr3_link2_accelerometer_top"/>
  </joint>
  <link name="left_fr3_link2_accelerometer_bottom">
      </link>
  <joint name="left_fr3_link2_accelerometer_bottom_joint" type="fixed">
    <origin rpy="1.5708 -1.5708 0.0" xyz="0.019737 -0.11875 -0.00155"/>
    <parent link="left_fr3_link2"/>
    <child link="left_fr3_link2_accelerometer_bottom"/>
  </joint>
  <joint name="left_fr3_joint2" type="revolute">
    <origin rpy="-1.57079632679 0 0" xyz="0 0 0"/>
    <parent link="left_fr3_link1"/>
    <child link="left_fr3_link2"/>
    <axis xyz="0 0 1"/>
    <limit effort="87.0" lower="-1.8361" upper="1.8361" velocity="2.62"/>
    <safety_controller k_position="100.0" k_velocity="40.0" soft_lower_limit="-1.8361" soft_upper_limit="1.8361"/>
    <position_based_velocity_limits deceleration_limit="2.585" velocity_offset="0.25"/>
    <dynamics D="1" K="7000" damping="0.003" friction="0.2" gear_ratio="120.0" motor_inertia="4.206399e-05" mu_coulomb="0" mu_viscous="16"/>
  </joint>
  <!-- sub-link defining detailed meshes for collision with environment -->
  <link name="left_fr3_link3">
    <visual name="left_fr3_link3_visual">
      <geometry>
        <mesh filename="fr3_meshes/visual/link3.dae"/>
      </geometry>
    </visual>
    <collision name="left_fr3_link3_collision">
      <geometry>
        <mesh filename="fr3_meshes/collision/link3.stl"/>
      </geometry>
    </collision>
    <inertial>
      <origin rpy="0 0 0" xyz="0.0407015686 -0.0048200565 -0.0289730823"/>
      <mass value="2.2449013699"/>
      <inertia ixx="0.0241014254724" ixy="0.00240469455904" ixz="-0.00285626927011" iyy="0.0197405326671" iyz="-0.00210421268389" izz="0.0190444944822"/>
    </inertial>
  </link>
  <link name="left_fr3_link3_accelerometer_top">
      </link>
  <joint name="left_fr3_link3_accelerometer_top_joint" type="fixed">
    <origin rpy="-1.5708 0.0 0.0" xyz="0.065099 0.077352 -0.00787"/>
    <parent link="left_fr3_link3"/>
    <child link="left_fr3_link3_accelerometer_top"/>
  </joint>
  <link name="left_fr3_link3_accelerometer_bottom">
      </link>
  <joint name="left_fr3_link3_accelerometer_bottom_joint" type="fixed">
    <origin rpy="1.5708 1.5708 0.0" xyz="0.062769 0.073756 0.00155"/>
    <parent link="left_fr3_link3"/>
    <child link="left_fr3_link3_accelerometer_bottom"/>
  </joint>
  <joint name="left_fr3_joint3" type="revolute">
    <origin rpy="1.57079632679 0 0" xyz="0 -0.316 0"/>
    <parent link="left_fr3_link2"/>
    <child link="left_fr3_link3"/>
    <axis xyz="0 0 1"/>
    <limit effort="87.0" lower="-2.9007" upper="2.9007" velocity="2.62"/>
    <safety_controller k_position="100.0" k_velocity="40.0" soft_lower_limit="-2.9007" soft_upper_limit="2.9007"/>
    <position_based_velocity_limits deceleration_limit="3.5" velocity_offset="0.2005"/>
    <dynamics D="1" K="7000" damping="0.003" friction="0.2" gear_ratio="120.0" motor_inertia="3.211626e-05" mu_coulomb="0" mu_viscous="16"/>
  </joint>
  <!-- sub-link defining detailed meshes for collision with environment -->
  <link name="left_fr3_link4">
    <visual name="left_fr3_link4_visual">
      <geometry>
        <mesh filename="fr3_meshes/visual/link4.dae"/>
      </geometry>
    </visual>
    <collision name="left_fr3_link4_collision">
      <geometry>
        <mesh filename="fr3_meshes/collision/link4.stl"/>
      </geometry>
    </collision>
    <inertial>
      <origin rpy="0 0 0" xyz="-0.0459100965 0.0630492960 -0.0085187868"/>
      <mass value="2.6155955791"/>
      <inertia ixx="0.0345299832191" ixy="0.0132255226598" ixz="0.0101514299848" iyy="0.028881621933" iyz="-0.00097628338707" izz="0.0412547117115"/>
    </inertial>
  </link>
  <link name="left_fr3_link4_accelerometer_top">
      </link>
  <joint name="left_fr3_link4_accelerometer_top_joint" type="fixed">
    <origin rpy="-1.5708 0.0 -3.1416" xyz="-0.0651 0.046252 -0.00787"/>
    <parent link="left_fr3_link4"/>
    <child link="left_fr3_link4_accelerometer_top"/>
  </joint>
  <link name="left_fr3_link4_accelerometer_bottom">
      </link>
  <joint name="left_fr3_link4_accelerometer_bottom_joint" type="fixed">
    <origin rpy="-1.5708 1.5708 0.0" xyz="-0.062775 0.049753 0.00155"/>
    <parent link="left_fr3_link4"/>
    <child link="left_fr3_link4_accelerometer_bottom"/>
  </joint>
  <joint name="left_fr3_joint4" type="revolute">
    <origin rpy="1.57079632679 0 0" xyz="0.0825 0 0"/>
    <parent link="left_fr3_link3"/>
    <child link="left_fr3_link4"/>
    <axis xyz="0 0 1"/>
    <limit effort="87.0" lower="-3.077" upper="-0.1169" velocity="2.62"/>
    <safety_controller k_position="100.0" k_velocity="40.0" soft_lower_limit="-3.077" soft_upper_limit="-0.1169"/>
    <position_based_velocity_limits deceleration_limit="4.0" velocity_offset="0.3542"/>
    <dynamics D="1" K="7000" damping="0.003" friction="0.2" gear_ratio="120.0" motor_inertia="3.211626e-05" mu_coulomb="0" mu_viscous="16"/>
  </joint>
  <!-- sub-link defining detailed meshes for collision with environment -->
  <link name="left_fr3_link5">
    <visual name="left_fr3_link5_visual">
      <geometry>
        <mesh filename="fr3_meshes/visual/link5.dae"/>
      </geometry>
    </visual>
    <collision name="left_fr3_link5_collision">
      <geometry>
        <mesh filename="fr3_meshes/collision/link5.stl"/>
      </geometry>
    </collision>
    <inertial>
      <origin rpy="0 0 0" xyz="-0.0016039605 0.0292536262 -0.0972965990"/>
      <mass value="2.3271207594"/>
      <inertia ixx="0.0516102784637" ixy="-0.00571517338778" ixz="-0.00356731676259" iyy="0.0478772971337" iyz="0.0106739851085" izz="0.0164236255794"/>
    </inertial>
  </link>
  <link name="left_fr3_link5_accelerometer_top">
      </link>
  <joint name="left_fr3_link5_accelerometer_top_joint" type="fixed">
    <origin rpy="-1.5708 0.0 0.0" xyz="-0.017363 0.085872 -0.00795"/>
    <parent link="left_fr3_link5"/>
    <child link="left_fr3_link5_accelerometer_top"/>
  </joint>
  <link name="left_fr3_link5_accelerometer_bottom">
      </link>
  <joint name="left_fr3_link5_accelerometer_bottom_joint" type="fixed">
    <origin rpy="1.5708 1.5708 0.0" xyz="-0.019742 0.082275 0.00146"/>
    <parent link="left_fr3_link5"/>
    <child link="left_fr3_link5_accelerometer_bottom"/>
  </joint>
  <joint name="left_fr3_joint5" type="revolute">
    <origin rpy="-1.57079632679 0 0" xyz="-0.0825 0.384 0"/>
    <parent link="left_fr3_link4"/>
    <child link="left_fr3_link5"/>
    <axis xyz="0 0 1"/>
    <limit effort="12.0" lower="-2.8763" upper="2.8763" velocity="5.26"/>
    <safety_controller k_position="100.0" k_velocity="40.0" soft_lower_limit="-2.8763" soft_upper_limit="2.8763"/>
    <position_based_velocity_limits deceleration_limit="17.0" velocity_offset="0.5738"/>
    <dynamics D="1" K="7000" damping="0.003" friction="0.2" gear_ratio="80.0" motor_inertia="3.211626e-05" mu_coulomb="0" mu_viscous="16"/>
  </joint>
  <!-- sub-link defining detailed meshes for collision with environment -->
  <link name="left_fr3_link6">
    <visual name="left_fr3_link6_visual">
      <geometry>
        <mesh filename="fr3_meshes/visual/link6.dae"/>
      </geometry>
    </visual>
    <collision name="left_fr3_link6_collision">
      <geometry>
        <mesh filename="fr3_meshes/collision/link6.stl"/>
      </geometry>
    </collision>
    <inertial>
      <origin rpy="0 0 0" xyz="0.0597131221 -0.0410294666 -0.0101692726"/>
      <mass value="1.8170376524"/>
      <inertia ixx="0.00541233359438" ixy="0.00619345636029" ixz="0.00142192893061" iyy="0.0140583295455" iyz="-0.00131407537411" izz="0.0160808179242"/>
    </inertial>
  </link>
  <joint name="left_fr3_joint6" type="revolute">
    <origin rpy="1.57079632679 0 0" xyz="0 0 0"/>
    <parent link="left_fr3_link5"/>
    <child link="left_fr3_link6"/>
    <axis xyz="0 0 1"/>
    <limit effort="12.0" lower="0.4398" upper="4.6216" velocity="4.18"/>
    <safety_controller k_position="100.0" k_velocity="40.0" soft_lower_limit="0.4398" soft_upper_limit="4.6216"/>
    <position_based_velocity_limits deceleration_limit="5.5" velocity_offset="0.4885"/>
    <dynamics D="1" K="7000" damping="0.003" friction="0.2" gear_ratio="80.0" motor_inertia="3.211626e-05" mu_coulomb="0" mu_viscous="16"/>
  </joint>
  <!-- sub-link defining detailed meshes for collision with environment -->
  <link name="left_fr3_link7">
    <visual name="left_fr3_link7_visual">
      <geometry>
        <mesh filename="fr3_meshes/visual/link7.dae"/>
      </geometry>
    </visual>
    <collision name="left_fr3_link7_collision">
      <geometry>
        <mesh filename="fr3_meshes/collision/link7.stl"/>
      </geometry>
    </collision>
    <inertial>
      <origin rpy="0 0 0" xyz="0.0045225817 0.0086261921 -0.0161633251"/>
      <mass value="0.6271432862"/>
      <inertia ixx="0.000210923891501" ixy="-2.43329911446e-05" ixz="4.56448039378e-05" iyy="0.000177185680024" iyz="8.74407022323e-05" izz="5.99319059966e-05"/>
    </inertial>
  </link>
  <joint name="left_fr3_joint7" type="revolute">
    <origin rpy="1.57079632679 0 0" xyz="0.088 0 0"/>
    <parent link="left_fr3_link6"/>
    <child link="left_fr3_link7"/>
    <axis xyz="0 0 1"/>
    <limit effort="12.0" lower="-3.0508" upper="3.0508" velocity="5.26"/>
    <safety_controller k_position="100.0" k_velocity="40.0" soft_lower_limit="-3.0508" soft_upper_limit="3.0508"/>
    <position_based_velocity_limits deceleration_limit="17.0" velocity_offset="0.4592"/>
    <dynamics D="1" K="7000" damping="0.003" friction="0.2" gear_ratio="80.0" motor_inertia="3.211626e-05" mu_coulomb="0" mu_viscous="16"/>
  </joint>
  <link name="left_fr3_link8"/>
  <joint name="left_fr3_joint8" type="fixed">
    <origin rpy="0 0 0" xyz="0 0 0.107"/>
    <parent link="left_fr3_link7"/>
    <child link="left_fr3_link8"/>
  </joint>
  <joint name="left_fr3_hand_joint" type="fixed">
    <parent link="left_fr3_link8"/>
    <child link="left_fr3_hand"/>
    <origin rpy="0 0 -0.785398163397" xyz="0 0 0"/>
  </joint>
  <!-- sub-link defining detailed meshes for collision with environment -->
  <link name="left_fr3_hand">
    <visual name="left_fr3_hand_visual">
      <geometry>
        <mesh filename="fr3_meshes/visual/hand.dae"/>
      </geometry>
    </visual>
    <collision name="left_fr3_hand_collision">
      <geometry>
        <mesh filename="fr3_meshes/collision/hand.stl"/>
      </geometry>
    </collision>
    <inertial>
      <origin rpy="0 0 0" xyz="-0.0000376 0.0119128 0.0207260"/>
      <mass value="0.6544"/>
      <inertia ixx="0.00186" ixy="0.0" ixz="0.0" iyy="0.0003" iyz="-2e-05" izz="0.00174"/>
    </inertial>
  </link>
  <!-- Define the hand_tcp frame -->
  <link name="left_fr3_hand_tcp"/>
  <joint name="left_fr3_hand_tcp_joint" type="fixed">
    <origin rpy="0 0 0" xyz="0 0 0.1034"/>
    <parent link="left_fr3_hand"/>
    <child link="left_fr3_hand_tcp"/>
  </joint>
  <link name="left_fr3_leftfinger">
    <visual name="left_fr3_leftfinger_visual">
      <geometry>
        <mesh filename="fr3_meshes/visual/finger.dae"/>
      </geometry>
    </visual>
    <!-- screw mount -->
    <collision>
      <origin rpy="0 0 0" xyz="0 18.5e-3 11e-3"/>
      <geometry>
        <box size="22e-3 15e-3 20e-3"/>
      </geometry>
    </collision>
    <!-- cartriage sledge -->
    <collision>
      <origin rpy="0 0 0" xyz="0 6.8e-3 2.2e-3"/>
      <geometry>
        <box size="22e-3 8.8e-3 3.8e-3"/>
      </geometry>
    </collision>
    <!-- diagonal finger -->
    <collision>
      <origin rpy="0.523598775598 0 0" xyz="0 15.9e-3 28.35e-3"/>
      <geometry>
        <box size="17.5e-3 7e-3 23.5e-3"/>
      </geometry>
    </collision>
    <!-- rubber tip with which to grasp -->
    <collision>
      <origin rpy="0 0 0" xyz="0 7.58e-3 45.25e-3"/>
      <geometry>
        <box size="17.5e-3 15.2e-3 18.5e-3"/>
      </geometry>
    </collision>
    <inertial>
      <origin rpy="0 0 0" xyz="0 0.0152850 0.0219675"/>
      <mass value="0.0291"/>
      <inertia ixx="8.49e-06" ixy="0.0" ixz="0.0" iyy="8.53e-06" iyz="-1.06e-06" izz="1.77e-06"/>
    </inertial>
  </link>
  <link name="left_fr3_rightfinger">
    <visual name="left_fr3_rightfinger_visual">
      <origin rpy="0 0 0" xyz="0 0 0"/>
      <geometry>
        <mesh filename="fr3_meshes/visual/finger.dae"/>
      </geometry>
    </visual>
    <!-- screw mount -->
    <collision>
      <origin rpy="0 0 0" xyz="0 18.5e-3 11e-3"/>
      <geometry>
        <box size="22e-3 15e-3 20e-3"/>
      </geometry>
    </collision>
    <!-- cartriage sledge -->
    <collision>
      <origin rpy="0 0 0" xyz="0 6.8e-3 2.2e-3"/>
      <geometry>
        <box size="22e-3 8.8e-3 3.8e-3"/>
      </geometry>
    </collision>
    <!-- diagonal finger -->
    <collision>
      <origin rpy="-0.523598775598 0 3.14159265359" xyz="0 15.9e-3 28.35e-3"/>
      <geometry>
        <box size="17.5e-3 7e-3 23.5e-3"/>
      </geometry>
    </collision>
    <!-- rubber tip with which to grasp -->
    <collision>
      <origin rpy="0 0 0" xyz="0 7.58e-3 45.25e-3"/>
      <geometry>
        <box size="17.5e-3 15.2e-3 18.5e-3"/>
      </geometry>
    </collision>
    <inertial>
      <origin rpy="0 0 0" xyz="0 0.0152850 0.0219675"/>
      <mass value="0.0291"/>
      <inertia ixx="8.49e-06" ixy="0.0" ixz="0.0" iyy="8.53e-06" iyz="-1.06e-06" izz="1.77e-06"/>
    </inertial>
  </link>
  <joint name="left_fr3_finger_joint1" type="prismatic">
    <parent link="left_fr3_hand"/>
    <child link="left_fr3_leftfinger"/>
    <origin rpy="0 0 0" xyz="0 0 0.0584"/>
    <axis xyz="0 1 0"/>
    <limit effort="100" lower="0.0" upper="0.04" velocity="0.2"/>
    <dynamics damping="0.3"/>
  </joint>
  <joint name="left_fr3_finger_joint2" type="prismatic">
    <parent link="left_fr3_hand"/>
    <child link="left_fr3_rightfinger"/>
    <origin rpy="0 0 3.14159265359" xyz="0 0 0.0584"/>
    <axis xyz="0 1 0"/>
    <limit effort="100" lower="0.0" upper="0.04" velocity="0.2"/>
    <mimic joint="left_fr3_finger_joint1"/>
    <dynamics damping="0.3"/>
  </joint>

  <!-- RIGHT ARM BODY -->
<!-- safety_distance: Minimum safety distance in [m] by which the collision volumes are expanded and which is enforced during robot motions -->
  <!-- robot_type: Namespace of the robot arm. Serves to differentiate between arms in case of multiple instances. -->
  <!-- joint_limits: description of the joint limits that comes from a YAML file. Example definition: ${xacro.load_yaml('$(find franka_description)/robots/fr3/joint_limits.yaml')} -->
  <!-- kinematics: description of the kinematics that comes from a YAML file. Example definition: ${xacro.load_yaml('$(find franka_description)/robots/fr3/kinematics.yaml')} -->
  <!-- inertials: description of the inertials that comes from a YAML file. Example definition: ${xacro.load_yaml('$(find franka_description)/robots/fr3/inertials.yaml')} -->
  <!-- dynamics: description of the dynamics that comes from a YAML file. Example definition: ${xacro.load_yaml('$(find franka_description)/robots/fr3/dynamics.yaml')} -->
  <joint name="right_fr3_base_joint" type="fixed">
    <parent link="right_fr3_root"/>
    <child link="right_fr3_link0"/>
    <origin rpy="0 0 0" xyz="0 0 0"/>
  </joint>
  <!-- sub-link defining detailed meshes for collision with environment -->
  <link name="right_fr3_link0">
    <visual name="right_fr3_link0_visual">
      <geometry>
        <mesh filename="fr3_meshes/visual/link0.dae"/>
      </geometry>
    </visual>
    <collision name="right_fr3_link0_collision">
      <geometry>
        <mesh filename="fr3_meshes/collision/link0.stl"/>
      </geometry>
    </collision>
    <inertial>
      <origin rpy="0 0 0" xyz="-0.0172 0.0004 0.0745"/>
      <mass value="2.3966"/>
      <inertia ixx="0.009" ixy="0.0" ixz="0.002" iyy="0.0115" iyz="0.0" izz="0.0085"/>
    </inertial>
  </link>
  <link name="right_fr3_link0_accelerometer_top">
      </link>
  <joint name="right_fr3_link0_accelerometer_top_joint" type="fixed">
    <origin rpy="3.1416 0.0 0.0" xyz="-0.017402 -0.007872 0.04715"/>
    <parent link="right_fr3_link0"/>
    <child link="right_fr3_link0_accelerometer_top"/>
  </joint>
  <link name="right_fr3_link0_accelerometer_bottom">
      </link>
  <joint name="right_fr3_link0_accelerometer_bottom_joint" type="fixed">
    <origin rpy="0.0 0.0 -1.5708" xyz="-0.019739 0.0015506 0.05075"/>
    <parent link="right_fr3_link0"/>
    <child link="right_fr3_link0_accelerometer_bottom"/>
  </joint>
  <!-- sub-link defining detailed meshes for collision with environment -->
  <link name="right_fr3_link1">
    <visual name="right_fr3_link1_visual">
      <geometry>
        <mesh filename="fr3_meshes/visual/link1.dae"/>
      </geometry>
    </visual>
    <collision name="right_fr3_link1_collision">
      <geometry>
        <mesh filename="fr3_meshes/collision/link1.stl"/>
      </geometry>
    </collision>
    <inertial>
      <origin rpy="0 0 0" xyz="0.0000004128 -0.0181251324 -0.0386035970"/>
      <mass value="2.9274653454"/>
      <inertia ixx="0.0239273164851" ixy="1.33179034557e-05" ixz="-0.000114047749186" iyy="0.0224821613276" iyz="-0.00199503206282" izz="0.00635009825853"/>
    </inertial>
  </link>
  <link name="right_fr3_link1_accelerometer_top">
      </link>
  <joint name="right_fr3_link1_accelerometer_top_joint" type="fixed">
    <origin rpy="-1.5708 0.0 3.1416" xyz="0.017402 -0.093352 -0.00787"/>
    <parent link="right_fr3_link1"/>
    <child link="right_fr3_link1_accelerometer_top"/>
  </joint>
  <link name="right_fr3_link1_accelerometer_bottom">
      </link>
  <joint name="right_fr3_link1_accelerometer_bottom_joint" type="fixed">
    <origin rpy="-1.5708 1.5708 0.0" xyz="0.01974 -0.08975 0.00155"/>
    <parent link="right_fr3_link1"/>
    <child link="right_fr3_link1_accelerometer_bottom"/>
  </joint>
  <joint name="right_fr3_joint1" type="revolute">
    <origin rpy="0 0 0" xyz="0 0 0.333"/>
    <parent link="right_fr3_link0"/>
    <child link="right_fr3_link1"/>
    <axis xyz="0 0 1"/>
    <limit effort="87.0" lower="-2.9007" upper="2.9007" velocity="2.62"/>
    <safety_controller k_position="100.0" k_velocity="40.0" soft_lower_limit="-2.9007" soft_upper_limit="2.9007"/>
    <position_based_velocity_limits deceleration_limit="6.0" velocity_offset="0.652"/>
    <dynamics D="1" K="7000" damping="0.003" friction="0.2" gear_ratio="120.0" motor_inertia="4.206399e-05" mu_coulomb="0" mu_viscous="16"/>
  </joint>
  <!-- sub-link defining detailed meshes for collision with environment -->
  <link name="right_fr3_link2">
    <visual name="right_fr3_link2_visual">
      <geometry>
        <mesh filename="fr3_meshes/visual/link2.dae"/>
      </geometry>
    </visual>
    <collision name="right_fr3_link2_collision">
      <geometry>
        <mesh filename="fr3_meshes/collision/link2.stl"/>
      </geometry>
    </collision>
    <inertial>
      <origin rpy="0 0 0" xyz="0.0031828864 -0.0743221644 0.0088146084"/>
      <mass value="2.9355370338"/>
      <inertia ixx="0.0419389462576" ixy="0.000202573315211" ixz="0.00407778422718" iyy="0.0251451488501" iyz="-0.00422521580066" izz="0.0617021447289"/>
    </inertial>
  </link>
  <link name="right_fr3_link2_accelerometer_top">
      </link>
  <joint name="right_fr3_link2_accelerometer_top_joint" type="fixed">
    <origin rpy="1.5708 0.0 3.1416" xyz="0.017403 -0.11715 0.00787"/>
    <parent link="right_fr3_link2"/>
    <child link="right_fr3_link2_accelerometer_top"/>
  </joint>
  <link name="right_fr3_link2_accelerometer_bottom">
      </link>
  <joint name="right_fr3_link2_accelerometer_bottom_joint" type="fixed">
    <origin rpy="1.5708 -1.5708 0.0" xyz="0.019737 -0.11875 -0.00155"/>
    <parent link="right_fr3_link2"/>
    <child link="right_fr3_link2_accelerometer_bottom"/>
  </joint>
  <joint name="right_fr3_joint2" type="revolute">
    <origin rpy="-1.57079632679 0 0" xyz="0 0 0"/>
    <parent link="right_fr3_link1"/>
    <child link="right_fr3_link2"/>
    <axis xyz="0 0 1"/>
    <limit effort="87.0" lower="-1.8361" upper="1.8361" velocity="2.62"/>
    <safety_controller k_position="100.0" k_velocity="40.0" soft_lower_limit="-1.8361" soft_upper_limit="1.8361"/>
    <position_based_velocity_limits deceleration_limit="2.585" velocity_offset="0.25"/>
    <dynamics D="1" K="7000" damping="0.003" friction="0.2" gear_ratio="120.0" motor_inertia="4.206399e-05" mu_coulomb="0" mu_viscous="16"/>
  </joint>
  <!-- sub-link defining detailed meshes for collision with environment -->
  <link name="right_fr3_link3">
    <visual name="right_fr3_link3_visual">
      <geometry>
        <mesh filename="fr3_meshes/visual/link3.dae"/>
      </geometry>
    </visual>
    <collision name="right_fr3_link3_collision">
      <geometry>
        <mesh filename="fr3_meshes/collision/link3.stl"/>
      </geometry>
    </collision>
    <inertial>
      <origin rpy="0 0 0" xyz="0.0407015686 -0.0048200565 -0.0289730823"/>
      <mass value="2.2449013699"/>
      <inertia ixx="0.0241014254724" ixy="0.00240469455904" ixz="-0.00285626927011" iyy="0.0197405326671" iyz="-0.00210421268389" izz="0.0190444944822"/>
    </inertial>
  </link>
  <link name="right_fr3_link3_accelerometer_top">
      </link>
  <joint name="right_fr3_link3_accelerometer_top_joint" type="fixed">
    <origin rpy="-1.5708 0.0 0.0" xyz="0.065099 0.077352 -0.00787"/>
    <parent link="right_fr3_link3"/>
    <child link="right_fr3_link3_accelerometer_top"/>
  </joint>
  <link name="right_fr3_link3_accelerometer_bottom">
      </link>
  <joint name="right_fr3_link3_accelerometer_bottom_joint" type="fixed">
    <origin rpy="1.5708 1.5708 0.0" xyz="0.062769 0.073756 0.00155"/>
    <parent link="right_fr3_link3"/>
    <child link="right_fr3_link3_accelerometer_bottom"/>
  </joint>
  <joint name="right_fr3_joint3" type="revolute">
    <origin rpy="1.57079632679 0 0" xyz="0 -0.316 0"/>
    <parent link="right_fr3_link2"/>
    <child link="right_fr3_link3"/>
    <axis xyz="0 0 1"/>
    <limit effort="87.0" lower="-2.9007" upper="2.9007" velocity="2.62"/>
    <safety_controller k_position="100.0" k_velocity="40.0" soft_lower_limit="-2.9007" soft_upper_limit="2.9007"/>
    <position_based_velocity_limits deceleration_limit="3.5" velocity_offset="0.2005"/>
    <dynamics D="1" K="7000" damping="0.003" friction="0.2" gear_ratio="120.0" motor_inertia="3.211626e-05" mu_coulomb="0" mu_viscous="16"/>
  </joint>
  <!-- sub-link defining detailed meshes for collision with environment -->
  <link name="right_fr3_link4">
    <visual name="right_fr3_link4_visual">
      <geometry>
        <mesh filename="fr3_meshes/visual/link4.dae"/>
      </geometry>
    </visual>
    <collision name="right_fr3_link4_collision">
      <geometry>
        <mesh filename="fr3_meshes/collision/link4.stl"/>
      </geometry>
    </collision>
    <inertial>
      <origin rpy="0 0 0" xyz="-0.0459100965 0.0630492960 -0.0085187868"/>
      <mass value="2.6155955791"/>
      <inertia ixx="0.0345299832191" ixy="0.0132255226598" ixz="0.0101514299848" iyy="0.028881621933" iyz="-0.00097628338707" izz="0.0412547117115"/>
    </inertial>
  </link>
  <link name="right_fr3_link4_accelerometer_top">
      </link>
  <joint name="right_fr3_link4_accelerometer_top_joint" type="fixed">
    <origin rpy="-1.5708 0.0 -3.1416" xyz="-0.0651 0.046252 -0.00787"/>
    <parent link="right_fr3_link4"/>
    <child link="right_fr3_link4_accelerometer_top"/>
  </joint>
  <link name="right_fr3_link4_accelerometer_bottom">
      </link>
  <joint name="right_fr3_link4_accelerometer_bottom_joint" type="fixed">
    <origin rpy="-1.5708 1.5708 0.0" xyz="-0.062775 0.049753 0.00155"/>
    <parent link="right_fr3_link4"/>
    <child link="right_fr3_link4_accelerometer_bottom"/>
  </joint>
  <joint name="right_fr3_joint4" type="revolute">
    <origin rpy="1.57079632679 0 0" xyz="0.0825 0 0"/>
    <parent link="right_fr3_link3"/>
    <child link="right_fr3_link4"/>
    <axis xyz="0 0 1"/>
    <limit effort="87.0" lower="-3.077" upper="-0.1169" velocity="2.62"/>
    <safety_controller k_position="100.0" k_velocity="40.0" soft_lower_limit="-3.077" soft_upper_limit="-0.1169"/>
    <position_based_velocity_limits deceleration_limit="4.0" velocity_offset="0.3542"/>
    <dynamics D="1" K="7000" damping="0.003" friction="0.2" gear_ratio="120.0" motor_inertia="3.211626e-05" mu_coulomb="0" mu_viscous="16"/>
  </joint>
  <!-- sub-link defining detailed meshes for collision with environment -->
  <link name="right_fr3_link5">
    <visual name="right_fr3_link5_visual">
      <geometry>
        <mesh filename="fr3_meshes/visual/link5.dae"/>
      </geometry>
    </visual>
    <collision name="right_fr3_link5_collision">
      <geometry>
        <mesh filename="fr3_meshes/collision/link5.stl"/>
      </geometry>
    </collision>
    <inertial>
      <origin rpy="0 0 0" xyz="-0.0016039605 0.0292536262 -0.0972965990"/>
      <mass value="2.3271207594"/>
      <inertia ixx="0.0516102784637" ixy="-0.00571517338778" ixz="-0.00356731676259" iyy="0.0478772971337" iyz="0.0106739851085" izz="0.0164236255794"/>
    </inertial>
  </link>
  <link name="right_fr3_link5_accelerometer_top">
      </link>
  <joint name="right_fr3_link5_accelerometer_top_joint" type="fixed">
    <origin rpy="-1.5708 0.0 0.0" xyz="-0.017363 0.085872 -0.00795"/>
    <parent link="right_fr3_link5"/>
    <child link="right_fr3_link5_accelerometer_top"/>
  </joint>
  <link name="right_fr3_link5_accelerometer_bottom">
      </link>
  <joint name="right_fr3_link5_accelerometer_bottom_joint" type="fixed">
    <origin rpy="1.5708 1.5708 0.0" xyz="-0.019742 0.082275 0.00146"/>
    <parent link="right_fr3_link5"/>
    <child link="right_fr3_link5_accelerometer_bottom"/>
  </joint>
  <joint name="right_fr3_joint5" type="revolute">
    <origin rpy="-1.57079632679 0 0" xyz="-0.0825 0.384 0"/>
    <parent link="right_fr3_link4"/>
    <child link="right_fr3_link5"/>
    <axis xyz="0 0 1"/>
    <limit effort="12.0" lower="-2.8763" upper="2.8763" velocity="5.26"/>
    <safety_controller k_position="100.0" k_velocity="40.0" soft_lower_limit="-2.8763" soft_upper_limit="2.8763"/>
    <position_based_velocity_limits deceleration_limit="17.0" velocity_offset="0.5738"/>
    <dynamics D="1" K="7000" damping="0.003" friction="0.2" gear_ratio="80.0" motor_inertia="3.211626e-05" mu_coulomb="0" mu_viscous="16"/>
  </joint>
  <!-- sub-link defining detailed meshes for collision with environment -->
  <link name="right_fr3_link6">
    <visual name="right_fr3_link6_visual">
      <geometry>
        <mesh filename="fr3_meshes/visual/link6.dae"/>
      </geometry>
    </visual>
    <collision name="right_fr3_link6_collision">
      <geometry>
        <mesh filename="fr3_meshes/collision/link6.stl"/>
      </geometry>
    </collision>
    <inertial>
      <origin rpy="0 0 0" xyz="0.0597131221 -0.0410294666 -0.0101692726"/>
      <mass value="1.8170376524"/>
      <inertia ixx="0.00541233359438" ixy="0.00619345636029" ixz="0.00142192893061" iyy="0.0140583295455" iyz="-0.00131407537411" izz="0.0160808179242"/>
    </inertial>
  </link>
  <joint name="right_fr3_joint6" type="revolute">
    <origin rpy="1.57079632679 0 0" xyz="0 0 0"/>
    <parent link="right_fr3_link5"/>
    <child link="right_fr3_link6"/>
    <axis xyz="0 0 1"/>
    <limit effort="12.0" lower="0.4398" upper="4.6216" velocity="4.18"/>
    <safety_controller k_position="100.0" k_velocity="40.0" soft_lower_limit="0.4398" soft_upper_limit="4.6216"/>
    <position_based_velocity_limits deceleration_limit="5.5" velocity_offset="0.4885"/>
    <dynamics D="1" K="7000" damping="0.003" friction="0.2" gear_ratio="80.0" motor_inertia="3.211626e-05" mu_coulomb="0" mu_viscous="16"/>
  </joint>
  <!-- sub-link defining detailed meshes for collision with environment -->
  <link name="right_fr3_link7">
    <visual name="right_fr3_link7_visual">
      <geometry>
        <mesh filename="fr3_meshes/visual/link7.dae"/>
      </geometry>
    </visual>
    <collision name="right_fr3_link7_collision">
      <geometry>
        <mesh filename="fr3_meshes/collision/link7.stl"/>
      </geometry>
    </collision>
    <inertial>
      <origin rpy="0 0 0" xyz="0.0045225817 0.0086261921 -0.0161633251"/>
      <mass value="0.6271432862"/>
      <inertia ixx="0.000210923891501" ixy="-2.43329911446e-05" ixz="4.56448039378e-05" iyy="0.000177185680024" iyz="8.74407022323e-05" izz="5.99319059966e-05"/>
    </inertial>
  </link>
  <joint name="right_fr3_joint7" type="revolute">
    <origin rpy="1.57079632679 0 0" xyz="0.088 0 0"/>
    <parent link="right_fr3_link6"/>
    <child link="right_fr3_link7"/>
    <axis xyz="0 0 1"/>
    <limit effort="12.0" lower="-3.0508" upper="3.0508" velocity="5.26"/>
    <safety_controller k_position="100.0" k_velocity="40.0" soft_lower_limit="-3.0508" soft_upper_limit="3.0508"/>
    <position_based_velocity_limits deceleration_limit="17.0" velocity_offset="0.4592"/>
    <dynamics D="1" K="7000" damping="0.003" friction="0.2" gear_ratio="80.0" motor_inertia="3.211626e-05" mu_coulomb="0" mu_viscous="16"/>
  </joint>
  <link name="right_fr3_link8"/>
  <joint name="right_fr3_joint8" type="fixed">
    <origin rpy="0 0 0" xyz="0 0 0.107"/>
    <parent link="right_fr3_link7"/>
    <child link="right_fr3_link8"/>
  </joint>
  <joint name="right_fr3_hand_joint" type="fixed">
    <parent link="right_fr3_link8"/>
    <child link="right_fr3_hand"/>
    <origin rpy="0 0 -0.785398163397" xyz="0 0 0"/>
  </joint>
  <!-- sub-link defining detailed meshes for collision with environment -->
  <link name="right_fr3_hand">
    <visual name="right_fr3_hand_visual">
      <geometry>
        <mesh filename="fr3_meshes/visual/hand.dae"/>
      </geometry>
    </visual>
    <collision name="right_fr3_hand_collision">
      <geometry>
        <mesh filename="fr3_meshes/collision/hand.stl"/>
      </geometry>
    </collision>
    <inertial>
      <origin rpy="0 0 0" xyz="-0.0000376 0.0119128 0.0207260"/>
      <mass value="0.6544"/>
      <inertia ixx="0.00186" ixy="0.0" ixz="0.0" iyy="0.0003" iyz="-2e-05" izz="0.00174"/>
    </inertial>
  </link>
  <!-- Define the hand_tcp frame -->
  <link name="right_fr3_hand_tcp"/>
  <joint name="right_fr3_hand_tcp_joint" type="fixed">
    <origin rpy="0 0 0" xyz="0 0 0.1034"/>
    <parent link="right_fr3_hand"/>
    <child link="right_fr3_hand_tcp"/>
  </joint>
  <link name="right_fr3_leftfinger">
    <visual name="right_fr3_leftfinger_visual">
      <geometry>
        <mesh filename="fr3_meshes/visual/finger.dae"/>
      </geometry>
    </visual>
    <!-- screw mount -->
    <collision>
      <origin rpy="0 0 0" xyz="0 18.5e-3 11e-3"/>
      <geometry>
        <box size="22e-3 15e-3 20e-3"/>
      </geometry>
    </collision>
    <!-- cartriage sledge -->
    <collision>
      <origin rpy="0 0 0" xyz="0 6.8e-3 2.2e-3"/>
      <geometry>
        <box size="22e-3 8.8e-3 3.8e-3"/>
      </geometry>
    </collision>
    <!-- diagonal finger -->
    <collision>
      <origin rpy="0.523598775598 0 0" xyz="0 15.9e-3 28.35e-3"/>
      <geometry>
        <box size="17.5e-3 7e-3 23.5e-3"/>
      </geometry>
    </collision>
    <!-- rubber tip with which to grasp -->
    <collision>
      <origin rpy="0 0 0" xyz="0 7.58e-3 45.25e-3"/>
      <geometry>
        <box size="17.5e-3 15.2e-3 18.5e-3"/>
      </geometry>
    </collision>
    <inertial>
      <origin rpy="0 0 0" xyz="0 0.0152850 0.0219675"/>
      <mass value="0.0291"/>
      <inertia ixx="8.49e-06" ixy="0.0" ixz="0.0" iyy="8.53e-06" iyz="-1.06e-06" izz="1.77e-06"/>
    </inertial>
  </link>
  <link name="right_fr3_rightfinger">
    <visual name="right_fr3_rightfinger_visual">
      <origin rpy="0 0 0" xyz="0 0 0"/>
      <geometry>
        <mesh filename="fr3_meshes/visual/finger.dae"/>
      </geometry>
    </visual>
    <!-- screw mount -->
    <collision>
      <origin rpy="0 0 0" xyz="0 18.5e-3 11e-3"/>
      <geometry>
        <box size="22e-3 15e-3 20e-3"/>
      </geometry>
    </collision>
    <!-- cartriage sledge -->
    <collision>
      <origin rpy="0 0 0" xyz="0 6.8e-3 2.2e-3"/>
      <geometry>
        <box size="22e-3 8.8e-3 3.8e-3"/>
      </geometry>
    </collision>
    <!-- diagonal finger -->
    <collision>
      <origin rpy="-0.523598775598 0 3.14159265359" xyz="0 15.9e-3 28.35e-3"/>
      <geometry>
        <box size="17.5e-3 7e-3 23.5e-3"/>
      </geometry>
    </collision>
    <!-- rubber tip with which to grasp -->
    <collision>
      <origin rpy="0 0 0" xyz="0 7.58e-3 45.25e-3"/>
      <geometry>
        <box size="17.5e-3 15.2e-3 18.5e-3"/>
      </geometry>
    </collision>
    <inertial>
      <origin rpy="0 0 0" xyz="0 0.0152850 0.0219675"/>
      <mass value="0.0291"/>
      <inertia ixx="8.49e-06" ixy="0.0" ixz="0.0" iyy="8.53e-06" iyz="-1.06e-06" izz="1.77e-06"/>
    </inertial>
  </link>
  <joint name="right_fr3_finger_joint1" type="prismatic">
    <parent link="right_fr3_hand"/>
    <child link="right_fr3_leftfinger"/>
    <origin rpy="0 0 0" xyz="0 0 0.0584"/>
    <axis xyz="0 1 0"/>
    <limit effort="100" lower="0.0" upper="0.04" velocity="0.2"/>
    <dynamics damping="0.3"/>
  </joint>
  <joint name="right_fr3_finger_joint2" type="prismatic">
    <parent link="right_fr3_hand"/>
    <child link="right_fr3_rightfinger"/>
    <origin rpy="0 0 3.14159265359" xyz="0 0 0.0584"/>
    <axis xyz="0 1 0"/>
    <limit effort="100" lower="0.0" upper="0.04" velocity="0.2"/>
    <mimic joint="right_fr3_finger_joint1"/>
    <dynamics damping="0.3"/>
  </joint>
</robot>